Workbook
Name DATA_GESTAO: '02. PARÂMETROS'!$B$5
Name FERIADOS_342: '02. PARÂMETROS'!$F$18:$F$40
Name FERIADOS_343: '02. PARÂMETROS'!$G$18:$G$40
Name FERIADOS_281: '02. PARÂMETROS'!$I$18:$I$40
Name LISTA_FRENTES: '02. PARÂMETROS'!$A$45:$A$121
Name LISTA_CAUSAS: '02. PARÂMETROS'!$E$45:$E$52

Sheet 00. GUIA
A1: TAF — GESTÃO DA EMPRESA (obras 342, 343 e 281) | E1: ◀ MENU
A2: Mesma arquitetura da WCR - GESTÃO DA EMPRESA. Comece pelo 00A. MENU.
A4: O que é | B4: A gestão da TAF em um arquivo: o que foi contratado (03), o plano de cada obra (04: 342 do estudo REV13, 343 do MOTOR TAF, 281 do cronograma da SANEAGO), o que aconteceu (05 a 08) e a comparação (08A a 12), com o MASTER CHECK no painel.
A5: Cores | B5: Azul = digitar. Preto = fórmula. Verde = vem de outra aba. Amarelo = falta dado ou decisão. Aba verde = dia a dia; cinza = só leitura; âmbar = ajuste eventual.
A6: Rotina da segunda | B6: 02 (data de corte) → 05B (apontamento da semana conferido) → 05C (restrições com dono e prazo) → 05A (compromisso da próxima semana, confirmado pelo engenheiro na sexta) → 01A (10 perguntas e 3 luzes) → PAUTA (1 decisão por obra).
A7: Fechamento do mês | B7: 06 (BM) → 07 (NF) → 08 (custos pagos) → 08A/08C (desvio e resultado) → 10 (caixa).
A8: Plano | B8: 342: plano do estudo REV13 (interno, pasta panorama do projeto), cenário 1 eventograma Anexo VII, copiado em azul na 04 com fonte. 343: MOTOR TAF. Plano novo: copiar de novo na 04 e conferir a 13. CHECKS e a CHECKS DA OPERAÇÃO. 281: cronograma físico-financeiro da SANEAGO (Cronograma FF x Gráficos) na 04, linhas 40 a 50; BMs 1 a 7 na 06; NFs da Medição 02 na 07; custos do consórcio TAF TECNOBOMBAS até maio/2026 na 08D, somados por mês e conta na 08. Obra gerida a 100% do contrato; a parte da TAF fica na 03 (F22). Ainda sem orçamento de custo, por isso margem e caixa da 281 aparecem SEM BASE.
A9: Atenção 342 | B9: O plano da 342 é o estudo REV13 sobre o eventograma Anexo VII (UN só mede na conclusão). R$ 993 mil do custo ainda estão sem cotação da TAF (SEM BASE), por isso o resultado aparece como SEM BASE no painel. Resultado e caixa da 342 são números internos.
A10: ROTINA — todo dia (engenheiro residente / apontador) | B10: Lançar o dia na 05B até 9h do dia seguinte: data, obra, frente, pessoas, serviço, quantidade e paradas com motivo. Foto de avanço de cada frente. Comparar o dia com o ritmo-alvo (343: 80 m/dia de PEAD, 10 m/dia de FoFo); se cair 2 dias seguidos, escalar na hora.
A11: ROTINA — toda segunda (gerente de contrato, Tiago) | B11: Sexta: o engenheiro confirma o compromisso da próxima semana na 05A e marca o que cumpriu. Segunda: PPC, efetivo e restrições na 01A; 1 causa por desvio (MO → planejamento → material → equipamento → projeto → cliente); 1 decisão por obra com dono e prazo.
A12: ROTINA — todo mês (diretoria, Thadeu) | B12: 01. PAINEL → MASTER CHECK antes de qualquer número. Fechar medição (06/07/08). Medido × previsto do plano (04): desvio > 10% vira pauta. Nunca decidir com número pendente: buscar o dado.
A16: ABRIR O MENU

Sheet 00A. MENU
A1: TAF — MENU
A2: Clique no botão para ir. Em toda aba, '◀ MENU' (canto superior direito) volta para cá.
A4: VISÃO | B4: 01 PAINEL | D4: 01C PLACAR SEMANAL | F4: 13 CHECKS
A6: CONTRATO E PLANO | B6: 02 PARÂMETROS | D6: 03 CONTRATOS | F6: 04 PLANO DAS OBRAS
A8: DIA A DIA | B8: 05 SEMANAS | D8: 06 MEDIÇÃO (BM) | F8: 07 NF E RECEBIMENTO | H8: 08 CUSTOS
A10: RESULTADO | B10: 08A CUSTO POR OBRA | D10: 08B TODAS AS OBRAS | F10: 08C RESULTADO | H10: 10 CAIXA | J10: 12 EVM
A12: REFERÊNCIA | B12: 00 GUIA | D12: 14 FONTES | F12: 15 CHANGELOG
A14: ROTEIRO DE USO
A15: TODA SEGUNDA (reunião, 90 min) | B15: 02: mude a data de corte | C15: → | D15: 05B e 05C: apontamento e restrições | E15: → | F15: 05A: compromisso da semana | G15: → | H15: 01A: 10 perguntas e 3 luzes | I15: → | J15: PAUTA: 1 decisão por obra
A17: TODO MÊS (fechamento) | B17: 06: lance o BM | C17: → | D17: 07: lance a NF | E17: → | F17: 08: lance os custos pagos | G17: → | H17: 08A e 08C: desvio e resultado | I17: → | J17: 10: caixa previsto × real
A19: QUANDO O PLANO MUDA | B19: 342: estudo novo (pasta panorama) · 343: MOTOR TAF | C19: → | D19: 343: rodar_taf.py | E19: → | F19: copiar na 04 (azul, com fonte) | G19: → | H19: 13: estudo em uso confere | I19: → | J19: 04 e 12: plano novo e EVM
A21: COMO FUNCIONA — da medição ao dinheiro (quem faz)
A22: Encarregado: executa e aponta | B22: → | C22: Engenheiro: monta o BM do mês | D22: → | E22: ◆ BM aprovado pelo fiscal? | F22: SIM → | G22: Administrativo: emite a NF (342: até o último dia útil do mês; 343: protocola no 1º dia útil) | H22: → | I22: Diretoria: confere o crédito em 30 dias (07)
E23: NÃO ↓ corrigir a memória de cálculo e reapresentar (06: situação EM ELABORAÇÃO)
A25: COMO FUNCIONA — do custo ao pagamento
A26: Compra ou folha | B26: → | C26: ◆ Tem obra e conta? | D26: SIM → | E26: Administrativo: lança na 08 e paga | F26: → | G26: Diretoria: lê a 08A (desvio por conta)
C27: NÃO ↓ não paga sem obra e conta (13. CHECKS acusa)
A29: OPERAÇÃO (rev1) | B29: 00A CICLO | D29: CRONOGRAMA | F29: HISTOGRAMA | H29: FLUXO PROJETADO
A31: OPERAÇÃO (rev1) | B31: DASHBOARD BI | D31: PAUTA DE SEGUNDA | F31: LINHA DE BASE | H31: CHECKS DA OPERAÇÃO
A33: GESTÃO (rev2) | B33: 01A GESTÃO DA SEMANA | D33: 05A COMPROMISSO | F33: 05B APONTAMENTO | H33: 05C RESTRIÇÕES
A35: OBRA 281 (rev3) | B35: 08D LANÇAMENTOS 281 | D35: 03 CONTRATOS (281)

Sheet 00A. CICLO DA OBRA
A2: CICLO DA OBRA: do orçamento ao caixa, na ordem
A3: Siga a ordem. Cada etapa lê a anterior. As duas últimas colunas mostram a situação de cada obra agora (fórmulas).
A5: Etapa | B5: O que responde | C5: Quem | D5: Quando | E5: Onde (clique) | F5: 342 agora | G5: 343 agora
A6: 1. Viabilidade e orçamento | B6: A obra cabe no contrato? Qual o custo previsto? | C6: Diretoria | D6: Antes de assinar; revisar se o contrato mudar | E6: FLUXO PROJETADO TAF | F6: ="Contrato R$ "&FIXED('03. CONTRATOS'!$B$8,0)&" · saídas previstas R$ "&FIXED('FLUXO PROJETADO TAF'!$S$32,0)&" · o estudo interno estima resultado após tributos de R$ "&FIXED('FLUXO PROJETADO TAF'!$C$19,0) -> Contrato R$ 3,258,000 · saídas previstas R$ 3,212,459 · o estudo interno estima resultado após tributos de R$ -231,416 | G6: ="Contrato R$ "&FIXED('03. CONTRATOS'!$D$8,0)&" · custo previsto R$ "&FIXED('04. PLANO DAS OBRAS'!$D$30,0)&" · o estudo interno estima resultado após tributos de R$ "&FIXED('04. PLANO DAS OBRAS'!$D$31,0)&IF(AND(ABS(N('04. PLANO DAS OBRAS'!$D$30)-N('04. PLANO DAS OBRAS'!$S$24)-N('13. CHECKS'!$E$16))>1,ABS(N('04. PLANO DAS OBRAS'!$D$30)-N('04. PLANO DAS OBRAS'!$S$24))>1)," (custo sem conferência na 04)",IF(ABS(N('04. PLANO DAS OBRAS'!$D$30)-N('04. PLANO DAS OBRAS'!$S$24))>1," (o caixa ainda não tem R$ "&FIXED(N('04. PLANO DAS OBRAS'!$D$30)-N('04. PLANO DAS OBRAS'!$S$24),0)&" desse custo: 05C R101)","")) -> Contrato R$ 5,226,634 · custo previsto R$ 3,702,036 · o estudo interno estima resultado após tributos de R$ 1,080,334 (o caixa ainda não tem R$ 96,418 desse custo: 05C R101)
A7: 2. Cronograma | B7: Quais etapas, em que datas, em que ordem? O que é crítico? | C7: Planejador e engenheiro residente | D7: No início; revisar todo mês | E7: CRONOGRAMA PROJECT | F7: ="Etapas: "&COUNTIFS('CRONOGRAMA PROJECT'!$B$7:$B$27,"342",'CRONOGRAMA PROJECT'!$BV$7:$BV$27,"Contrato")&" · "&TEXT(DAY(_xlfn.MINIFS('CRONOGRAMA PROJECT'!$D$7:$D$27,'CRONOGRAMA PROJECT'!$BW$7:$BW$27,"342")),"00")&"/"&TEXT(MONTH(_xlfn.MINIFS('CRONOGRAMA PROJECT'!$D$7:$D$27,'CRONOGRAMA PROJECT'!$BW$7:$BW$27,"342")),"00")&"/"&RIGHT(YEAR(_xlfn.MINIFS('CRONOGRAMA PROJECT'!$D$7:$D$27,'CRONOGRAMA PROJECT'!$BW$7:$BW$27,"342")),2)&" a "&TEXT(DAY(_xlfn.MAXIFS('CRONOGRAMA PROJECT'!$E$7:$E$27,'CRONOGRAMA PROJECT'!$BW$7:$BW$27,"342")),"00")&"/"&TEXT(MONTH(_xlfn.MAXIFS('CRONOGRAMA PROJECT'!$E$7:$E$27,'CRONOGRAMA PROJECT'!$BW$7:$BW$27,"342")),"00")&"/"&RIGHT(YEAR(_xlfn.MAXIFS('CRONOGRAMA PROJECT'!$E$7:$E$27,'CRONOGRAMA PROJECT'!$BW$7:$BW$27,"342")),2)&" · sem predecessora: "&COUNTIFS('CRONOGRAMA PROJECT'!$B$7:$B$27,"342",'CRONOGRAMA PROJECT'!$BV$7:$BV$27,"Contrato",'CRONOGRAMA PROJECT'!$G$7:$G$27,"",'CRONOGRAMA PROJECT'!$H$7:$H$27,"",'CRONOGRAMA PROJECT'!$I$7:$I$27,"") -> Etapas: 11 · 03/09/26 a 27/08/27 · sem predecessora: 11 | G7: ="Etapas: "&COUNTIFS('CRONOGRAMA PROJECT'!$B$7:$B$27,"343",'CRONOGRAMA PROJECT'!$BV$7:$BV$27,"Contrato")&" · "&TEXT(DAY(_xlfn.MINIFS('CRONOGRAMA PROJECT'!$D$7:$D$27,'CRONOGRAMA PROJECT'!$BW$7:$BW$27,"343")),"00")&"/"&TEXT(MONTH(_xlfn.MINIFS('CRONOGRAMA PROJECT'!$D$7:$D$27,'CRONOGRAMA PROJECT'!$BW$7:$BW$27,"343")),"00")&"/"&RIGHT(YEAR(_xlfn.MINIFS('CRONOGRAMA PROJECT'!$D$7:$D$27,'CRONOGRAMA PROJECT'!$BW$7:$BW$27,"343")),2)&" a "&TEXT(DAY(_xlfn.MAXIFS('CRONOGRAMA PROJECT'!$E$7:$E$27,'CRONOGRAMA PROJECT'!$BW$7:$BW$27,"343")),"00")&"/"&TEXT(MONTH(_xlfn.MAXIFS('CRONOGRAMA PROJECT'!$E$7:$E$27,'CRONOGRAMA PROJECT'!$BW$7:$BW$27,"343")),"00")&"/"&RIGHT(YEAR(_xlfn.MAXIFS('CRONOGRAMA PROJECT'!$E$7:$E$27,'CRONOGRAMA PROJECT'!$BW$7:$BW$27,"343")),2)&" · sem predecessora: "&COUNTIFS('CRONOGRAMA PROJECT'!$B$7:$B$27,"343",'CRONOGRAMA PROJECT'!$BV$7:$BV$27,"Contrato",'CRONOGRAMA PROJECT'!$G$7:$G$27,"",'CRONOGRAMA PROJECT'!$H$7:$H$27,"",'CRONOGRAMA PROJECT'!$I$7:$I$27,"") -> Etapas: 5 · 01/09/26 a 31/05/27 · sem predecessora: 5
A8: 3. Restrições e lookahead | B8: O que falta para liberar as próximas 6 semanas? | C8: Engenheiro residente | D8: Sexta | E8: PAUTA DE SEGUNDA TAF | F8: ="Começam em 42 dias: "&COUNTIFS('CRONOGRAMA PROJECT'!$B$7:$B$27,"342",'CRONOGRAMA PROJECT'!$BV$7:$BV$27,"Contrato",'CRONOGRAMA PROJECT'!$D$7:$D$27,">"&DATA_GESTAO,'CRONOGRAMA PROJECT'!$D$7:$D$27,"<="&DATA_GESTAO+42)&" · críticas: "&IF(COUNTIFS('CRONOGRAMA PROJECT'!$B$7:$B$27,"342",'CRONOGRAMA PROJECT'!$N$7:$N$27,"sem rede")=COUNTIFS('CRONOGRAMA PROJECT'!$B$7:$B$27,"342"),"sem rede",COUNTIFS('CRONOGRAMA PROJECT'!$B$7:$B$27,"342",'CRONOGRAMA PROJECT'!$N$7:$N$27,"CRÍTICA")&IF(COUNTIFS('CRONOGRAMA PROJECT'!$B$7:$B$27,"342",'CRONOGRAMA PROJECT'!$N$7:$N$27,"sem rede")>0," ("&COUNTIFS('CRONOGRAMA PROJECT'!$B$7:$B$27,"342",'CRONOGRAMA PROJECT'!$N$7:$N$27,"sem rede")&" sem rede)",""))&" · ocorrências e pendências do cliente: "&IF(COUNTIFS('05. SEMANAS'!$A$5:$A$64,'02. PARÂMETROS'!$B$5,'05. SEMANAS'!$B$5:$B$64,"342")=0,"sem lançamento",'01C. PLACAR SEMANAL'!C11) -> Começam em 42 dias: 5 · críticas: sem rede · ocorrências e pendências do cliente: 56 | G8: ="Começam em 42 dias: "&COUNTIFS('CRONOGRAMA PROJECT'!$B$7:$B$27,"343",'CRONOGRAMA PROJECT'!$BV$7:$BV$27,"Contrato",'CRONOGRAMA PROJECT'!$D$7:$D$27,">"&DATA_GESTAO,'CRONOGRAMA PROJECT'!$D$7:$D$27,"<="&DATA_GESTAO+42)&" · críticas: "&IF(COUNTIFS('CRONOGRAMA PROJECT'!$B$7:$B$27,"343",'CRONOGRAMA PROJECT'!$N$7:$N$27,"sem rede")=COUNTIFS('CRONOGRAMA PROJECT'!$B$7:$B$27,"343"),"sem rede",COUNTIFS('CRONOGRAMA PROJECT'!$B$7:$B$27,"343",'CRONOGRAMA PROJECT'!$N$7:$N$27,"CRÍTICA")&IF(COUNTIFS('CRONOGRAMA PROJECT'!$B$7:$B$27,"343",'CRONOGRAMA PROJECT'!$N$7:$N$27,"sem rede")>0," ("&COUNTIFS('CRONOGRAMA PROJECT'!$B$7:$B$27,"343",'CRONOGRAMA PROJECT'!$N$7:$N$27,"sem rede")&" sem rede)",""))&" · ocorrências e pendências do cliente: "&IF(COUNTIFS('05. SEMANAS'!$A$5:$A$64,'02. PARÂMETROS'!$B$5,'05. SEMANAS'!$B$5:$B$64,"343")=0,"sem lançamento",'01C. PLACAR SEMANAL'!D11) -> Começam em 42 dias: 0 · críticas: sem rede · ocorrências e pendências do cliente: 11
A9: 4. Plano semanal | B9: Quanto cada equipe promete entregar na semana? | C9: Engenheiro com encarregados | D9: Sexta | E9: 05A. COMPROMISSO DA SEMANA | F9: ="PPC da semana: "&IF(COUNTIFS('05. SEMANAS'!$A$5:$A$64,'02. PARÂMETROS'!$B$5,'05. SEMANAS'!$B$5:$B$64,"342")=0,"sem lançamento",TEXT('01C. PLACAR SEMANAL'!C9,"0%")) -> PPC da semana: sem compromisso | G9: ="PPC da semana: "&IF(COUNTIFS('05. SEMANAS'!$A$5:$A$64,'02. PARÂMETROS'!$B$5,'05. SEMANAS'!$B$5:$B$64,"343")=0,"sem lançamento",TEXT('01C. PLACAR SEMANAL'!D9,"0%")) -> PPC da semana: sem compromisso
A10: 5. Controle diário | B10: O que foi feito hoje, com que gente? | C10: Encarregado e apontador | D10: Todo dia | E10: 05B. APONTAMENTO DIÁRIO | F10: ="Apontamentos ÷ dias úteis: "&IF(COUNTIFS('05. SEMANAS'!$A$5:$A$64,'02. PARÂMETROS'!$B$5,'05. SEMANAS'!$B$5:$B$64,"342")=0,"sem lançamento",TEXT('01C. PLACAR SEMANAL'!C10,"0%"))&" · efetivo ÷ previsto: "&IF(COUNTIFS('05. SEMANAS'!$A$5:$A$64,'02. PARÂMETROS'!$B$5,'05. SEMANAS'!$B$5:$B$64,"342")=0,"sem lançamento",TEXT('01C. PLACAR SEMANAL'!C8,"0%")) -> Apontamentos ÷ dias úteis: 0% · efetivo ÷ previsto: sem apontamento | G10: ="Apontamentos ÷ dias úteis: "&IF(COUNTIFS('05. SEMANAS'!$A$5:$A$64,'02. PARÂMETROS'!$B$5,'05. SEMANAS'!$B$5:$B$64,"343")=0,"sem lançamento",TEXT('01C. PLACAR SEMANAL'!D10,"0%"))&" · efetivo ÷ previsto: "&IF(COUNTIFS('05. SEMANAS'!$A$5:$A$64,'02. PARÂMETROS'!$B$5,'05. SEMANAS'!$B$5:$B$64,"343")=0,"sem lançamento",TEXT('01C. PLACAR SEMANAL'!D8,"0%")) -> Apontamentos ÷ dias úteis: 0% · efetivo ÷ previsto: sem apontamento
A11: 6. Histograma | B11: Quanta gente por mês e por semana, previsto x real? | C11: Engenheiro residente | D11: Semanal (olhar) | E11: HISTOGRAMA PLANEJADO | F11: ="Previsto no mês do corte: pico "&FIXED(INDEX('HISTOGRAMA PLANEJADO'!$B$8:$B$23,MATCH(DATE(YEAR(DATA_GESTAO),MONTH(DATA_GESTAO),1),'HISTOGRAMA PLANEJADO'!$A$8:$A$23,0)),0)&" pessoas · realizado: "&IF(ISNUMBER(INDEX('HISTOGRAMA PLANEJADO'!$I$8:$I$23,MATCH(DATE(YEAR(DATA_GESTAO),MONTH(DATA_GESTAO),1),'HISTOGRAMA PLANEJADO'!$A$8:$A$23,0))),"lançado","sem lançamento") -> Previsto no mês do corte: pico 23 pessoas · realizado: sem lançamento | G11: ="Previsto no mês do corte: pico "&FIXED(INDEX('HISTOGRAMA PLANEJADO'!$B$29:$B$44,MATCH(DATE(YEAR(DATA_GESTAO),MONTH(DATA_GESTAO),1),'HISTOGRAMA PLANEJADO'!$A$29:$A$44,0)),0)&" pessoas · realizado: "&IF(ISNUMBER(INDEX('HISTOGRAMA PLANEJADO'!$I$29:$I$44,MATCH(DATE(YEAR(DATA_GESTAO),MONTH(DATA_GESTAO),1),'HISTOGRAMA PLANEJADO'!$A$29:$A$44,0))),"lançado","sem lançamento") -> Previsto no mês do corte: pico 11 pessoas · realizado: sem lançamento
A12: 7. Medição | B12: O que foi feito já virou BM e dinheiro? | C12: Engenheiro e administrativo | D12: Fechamento do mês | E12: 06. MEDIÇÃO (BM) | F12: ="Medido até o corte: "&IF(COUNTIFS('06. MEDIÇÃO (BM)'!$B$5:$B$44,"342",'06. MEDIÇÃO (BM)'!$G$5:$G$44,"<>")=0,"sem lançamento","R$ "&FIXED('08B. TODAS AS OBRAS'!C5,0)&" ("&TEXT('08B. TODAS AS OBRAS'!D5,"0%")&" do contrato)")&" · previsto até o último BM fechado R$ "&FIXED('08B. TODAS AS OBRAS'!E5,0) -> Medido até o corte: sem lançamento · previsto até o último BM fechado R$ 0 | G12: ="Medido até o corte: "&IF(COUNTIFS('06. MEDIÇÃO (BM)'!$B$5:$B$44,"343",'06. MEDIÇÃO (BM)'!$G$5:$G$44,"<>")=0,"sem lançamento","R$ "&FIXED('08B. TODAS AS OBRAS'!C6,0)&" ("&TEXT('08B. TODAS AS OBRAS'!D6,"0%")&" do contrato)")&" · previsto até o último BM fechado R$ "&FIXED('08B. TODAS AS OBRAS'!E6,0) -> Medido até o corte: sem lançamento · previsto até o último BM fechado R$ 0
A13: 8. Custo | B13: Quanto custou, por obra e mês, contra o previsto? | C13: Administrativo | D13: Todo pagamento; fechamento do mês | E13: 08. CUSTOS | F13: ="Custo lançado até o corte: "&IF(COUNTIFS('08. CUSTOS'!$C$5:$C$404,"342",'08. CUSTOS'!$F$5:$F$404,"<>")=0,"sem lançamento","R$ "&FIXED('08B. TODAS AS OBRAS'!G5,0))&" · previsto até o corte R$ "&FIXED('08B. TODAS AS OBRAS'!H5,0) -> Custo lançado até o corte: sem lançamento · previsto até o corte R$ 29,526 | G13: ="Custo lançado até o corte: "&IF(COUNTIFS('08. CUSTOS'!$C$5:$C$404,"343",'08. CUSTOS'!$F$5:$F$404,"<>")=0,"sem lançamento","R$ "&FIXED('08B. TODAS AS OBRAS'!G6,0))&" · previsto até o corte R$ "&FIXED('08B. TODAS AS OBRAS'!H6,0) -> Custo lançado até o corte: sem lançamento · previsto até o corte R$ 820,643
A14: 9. Caixa | B14: Quanto entra e sai; qual o pior saldo e quando? | C14: Diretoria e administrativo | D14: Segunda | E14: FLUXO PROJETADO TAF | F14: ="Pior saldo previsto R$ "&FIXED('FLUXO PROJETADO TAF'!$C$14,0)&" em "&CHOOSE(MONTH('FLUXO PROJETADO TAF'!$C$15),"jan","fev","mar","abr","mai","jun","jul","ago","set","out","nov","dez")&"/"&RIGHT(YEAR('FLUXO PROJETADO TAF'!$C$15),2)&" · capital R$ "&FIXED('FLUXO PROJETADO TAF'!$C$16,0) -> Pior saldo previsto R$ -1,151,142 em fev/27 · capital R$ 1,323,813 | G14: ="Pior saldo previsto R$ "&FIXED('FLUXO PROJETADO TAF'!$D$14,0)&" em "&CHOOSE(MONTH('FLUXO PROJETADO TAF'!$D$15),"jan","fev","mar","abr","mai","jun","jul","ago","set","out","nov","dez")&"/"&RIGHT(YEAR('FLUXO PROJETADO TAF'!$D$15),2)&" · capital R$ "&FIXED('FLUXO PROJETADO TAF'!$D$16,0) -> Pior saldo previsto R$ -1,401,326 em nov/26 · capital R$ 1,611,524
A15: 10. Placar | B15: Cumprimos? IDP, custo, PPC, adoção do apontamento. | C15: Diretoria | D15: Segunda | E15: 01C. PLACAR SEMANAL | F15: ="IDP: "&IF(COUNTIFS('06. MEDIÇÃO (BM)'!$B$5:$B$44,"342",'06. MEDIÇÃO (BM)'!$G$5:$G$44,"<>")=0,"sem lançamento",IF('08B. TODAS AS OBRAS'!E5=0,"previsto zero",TEXT('08B. TODAS AS OBRAS'!C5/'08B. TODAS AS OBRAS'!E5,"0,00")))&" · custo ÷ previsto: "&IF(COUNTIFS('08. CUSTOS'!$C$5:$C$404,"342",'08. CUSTOS'!$F$5:$F$404,"<>")=0,"sem lançamento",TEXT(IFERROR('08B. TODAS AS OBRAS'!G5/'08B. TODAS AS OBRAS'!H5,0),"0,00")) -> IDP: sem lançamento · custo ÷ previsto: sem lançamento | G15: ="IDP: "&IF(COUNTIFS('06. MEDIÇÃO (BM)'!$B$5:$B$44,"343",'06. MEDIÇÃO (BM)'!$G$5:$G$44,"<>")=0,"sem lançamento",IF('08B. TODAS AS OBRAS'!E6=0,"previsto zero",TEXT('08B. TODAS AS OBRAS'!C6/'08B. TODAS AS OBRAS'!E6,"0,00")))&" · custo ÷ previsto: "&IF(COUNTIFS('08. CUSTOS'!$C$5:$C$404,"343",'08. CUSTOS'!$F$5:$F$404,"<>")=0,"sem lançamento",TEXT(IFERROR('08B. TODAS AS OBRAS'!G6/'08B. TODAS AS OBRAS'!H6,0),"0,00")) -> IDP: sem lançamento · custo ÷ previsto: sem lançamento
A16: 11. Decisão | B16: Qual a decisão, com dono e prazo? | C16: Diretoria e engenheiro | D16: Segunda, 90 minutos | E16: PAUTA DE SEGUNDA TAF | F16: ="Decisões abertas na pauta (proposta, aberta ou aprovada): "&(COUNTIF('PAUTA DE SEGUNDA TAF'!$D$64:$D$77,"PROPOSTA")+COUNTIF('PAUTA DE SEGUNDA TAF'!$D$64:$D$77,"ABERTA")+COUNTIF('PAUTA DE SEGUNDA TAF'!$D$64:$D$77,"APROVADA"))&" (342, 343 e 281)" -> Decisões abertas na pauta (proposta, aberta ou aprovada): 14 (342, 343 e 281) | G16: ="Decisões abertas na pauta (proposta, aberta ou aprovada): "&(COUNTIF('PAUTA DE SEGUNDA TAF'!$D$64:$D$77,"PROPOSTA")+COUNTIF('PAUTA DE SEGUNDA TAF'!$D$64:$D$77,"ABERTA")+COUNTIF('PAUTA DE SEGUNDA TAF'!$D$64:$D$77,"APROVADA"))&" (342, 343 e 281)" -> Decisões abertas na pauta (proposta, aberta ou aprovada): 14 (342, 343 e 281)
A19: ROTINA
A20: Todo dia | B20: Encarregado manda o apontamento e a foto; o apontador confere. Escalar se o ritmo cair 2 dias seguidos (roteiros diários por obra).
A21: Sexta | B21: Engenheiro residente: restrições das próximas 6 semanas na 05C e compromisso da próxima semana confirmado na 05A (o PPC sai sozinho na 05. SEMANAS).
A22: Segunda | B22: Mudar a data de corte (02), conferir o apontamento da semana (05B), ler as luzes (01A), o placar (01C), a PAUTA DE SEGUNDA TAF e o MASTER CHECK (13). Uma decisão por obra, com dono e prazo.
A23: Fim do mês | B23: Lançar o BM (06), a NF (07) e os custos pagos (08); lançar o % físico das etapas na coluna J do CRONOGRAMA PROJECT (a 12. EVM calcula o valor agregado a custo); conferir a LINHA DE BASE TAF.

Sheet CRONOGRAMA PROJECT
A2: CRONOGRAMA PROJECT: as duas obras, etapa por etapa, com caminho crítico
A3: Datas: primeiro e último mês com valor no cronograma (dia 1 do primeiro mês até o último dia do último mês). Predecessoras entre etapas: nenhuma fonte traz; as colunas amarelas G a I ficam para você digitar. Sem elas o caminho crítico não vale (a coluna Situação mostra 'sem rede'). Na tabela de eventos (linha 72), o antecessor da aba 37 do estudo REV13 liga eventos da mesma etapa; os marcos do fim da obra estão na linha 107.
A4: Fonte: 342 = eventograma Anexo VII (Eventograma 49/2024): valor de cada evento e datas de execução do plano do estudo REV13 (aba 05), na tabela de eventos da linha 72 em diante. 343 = mesmo arquivo, aba 343 - CRONOGRAMA (cronograma CAESB, Mês 1 = set/26, OS em 01/09/2026). Linhas 343-M = plano do motor, MOTOR TAF\ESTUDOS\TAF 343 CAESB SOBRADINHO - PLANEJAMENTO.xlsx, aba 13 PLANO (27/09/2026 17:51): referência de data, valor e custo; não somam com o contrato. | Q4: =IF(AND(TODAY()>=Q$6,TODAY()<=Q$6+6),"▲","") | R4: =IF(AND(TODAY()>=R$6,TODAY()<=R$6+6),"▲","") | S4: =IF(AND(TODAY()>=S$6,TODAY()<=S$6+6),"▲","") | T4: =IF(AND(TODAY()>=T$6,TODAY()<=T$6+6),"▲","") | U4: =IF(AND(TODAY()>=U$6,TODAY()<=U$6+6),"▲","") | V4: =IF(AND(TODAY()>=V$6,TODAY()<=V$6+6),"▲","") | W4: =IF(AND(TODAY()>=W$6,TODAY()<=W$6+6),"▲","") -> ▲ | X4: =IF(AND(TODAY()>=X$6,TODAY()<=X$6+6),"▲","") | ... BR4: =IF(AND(TODAY()>=BR$6,TODAY()<=BR$6+6),"▲","")
A5: ="Rede: "&SUMPRODUCT(--($G$7:$I$27<>""))&" predecessoras digitadas · etapas críticas: "&IF(COUNTIF($N$7:$N$27,"sem rede")=ROWS($N$7:$N$27),"sem rede",COUNTIF($N$7:$N$27,"CRÍTICA"))&" · problemas de checagem: "&COUNTIFS($P$7:$P$27,"<>ok")&" · data de gestão (02. PARÂMETROS): "&TEXT(DATA_GESTAO,"dd/mm")&"/"&YEAR(DATA_GESTAO) -> Rede: 0 predecessoras digitadas · etapas críticas: sem rede · problemas de checagem: 0 · data de gestão (02. PARÂMETROS): 16/10/2026 | Q5: =IF(AND(DATA_GESTAO>=Q$6,DATA_GESTAO<=Q$6+6),"▼","") | R5: =IF(AND(DATA_GESTAO>=R$6,DATA_GESTAO<=R$6+6),"▼","") | S5: =IF(AND(DATA_GESTAO>=S$6,DATA_GESTAO<=S$6+6),"▼","") | T5: =IF(AND(DATA_GESTAO>=T$6,DATA_GESTAO<=T$6+6),"▼","") | U5: =IF(AND(DATA_GESTAO>=U$6,DATA_GESTAO<=U$6+6),"▼","") | V5: =IF(AND(DATA_GESTAO>=V$6,DATA_GESTAO<=V$6+6),"▼","") | W5: =IF(AND(DATA_GESTAO>=W$6,DATA_GESTAO<=W$6+6),"▼","") -> ▼ | X5: =IF(AND(DATA_GESTAO>=X$6,DATA_GESTAO<=X$6+6),"▼","") | ... BR5: =IF(AND(DATA_GESTAO>=BR$6,DATA_GESTAO<=BR$6+6),"▼","")
A6: ID | B6: Obra | C6: Etapa | D6: Início | E6: Fim | F6: Duração (dias) | G6: Predecessora 1 | H6: Predecessora 2 | I6: Predecessora 3 | J6: % físico (lançar do BM) | K6: Valor da etapa (R$) | L6: Custo planejado (R$) | M6: Folga (dias) | N6: Situação | O6: Valor medido (R$) | P6: Checagem | Q6: =MIN('03. CONTRATOS'!$B$10,'03. CONTRATOS'!$D$10)-WEEKDAY(MIN('03. CONTRATOS'!$B$10,'03. CONTRATOS'!$D$10),2)+1 -> 46265 | R6: =Q6+7 -> 46272 | S6: =R6+7 -> 46279 | T6: =S6+7 -> 46286 | U6: =T6+7 -> 46293 | V6: =U6+7 -> 46300 | W6: =V6+7 -> 46307 | X6: =W6+7 -> 46314 | Y6: =X6+7 -> 46321 | ... BR6: =BQ6+7 -> 46636 | BT6: Início fixado (fonte) | BU6: Fim fixado (fonte) | BV6: Camada | BW6: Rede | BX6: Fim tarde | BY6: Início tarde | BZ6: Chave (auxiliar) | CA6: Predecessoras na rede (auxiliar)
A7: 342-01 | B7: 342 | C7: CANTEIRO DE OBRAS | D7: =IF(BT7="","",MAX(BT7,IF($G7="",0,_xlfn.MAXIFS($E$6:$E6,$A$6:$A6,$G7)+1),IF($H7="",0,_xlfn.MAXIFS($E$6:$E6,$A$6:$A6,$H7)+1),IF($I7="",0,_xlfn.MAXIFS($E$6:$E6,$A$6:$A6,$I7)+1))) -> 46314 | E7: =IF(D7="","",D7+F7-1) -> 46604 | F7: =IF(OR(BT7="",BU7=""),"",BU7-BT7+1) -> 291 | K7: =$P33 -> 122394 | L7: pendente | M7: =IF(OR(BX7="",E7=""),"",BX7-E7) -> 22 | N7: =IF(M7="","",IF(CA7=0,"sem rede",IF(M7<=0,"CRÍTICA",""))) -> sem rede | O7: =IF(OR(J7="",K7=""),"",J7*K7) | P7: =IF(OR(BT7="",BU7=""),"sem data",IF(OR(AND(G7<>"",COUNTIF($A$7:$A$27,G7)=0),AND(H7<>"",COUNTIF($A$7:$A$27,H7)=0),AND(I7<>"",COUNTIF($A$7:$A$27,I7)=0)),"predecessora inexistente",IF(OR(AND(G7<>"",COUNTIF($A$6:$A6,G7)=0),AND(H7<>"",COUNTIF($A$6:$A6,H7)=0),AND(I7<>"",COUNTIF($A$6:$A6,I7)=0)),"predecessora abaixo da tarefa","ok"))) -> ok | Q7: =IF(OR($D7="",$E7=""),"",IF(AND($D7<=Q$6+6,$E7>=Q$6),IF($N7="CRÍTICA","C","P"),"")) | R7: =IF(OR($D7="",$E7=""),"",IF(AND($D7<=R$6+6,$E7>=R$6),IF($N7="CRÍTICA","C","P"),"")) | S7: =IF(OR($D7="",$E7=""),"",IF(AND($D7<=S$6+6,$E7>=S$6),IF($N7="CRÍTICA","C","P"),"")) | T7: =IF(OR($D7="",$E7=""),"",IF(AND($D7<=T$6+6,$E7>=T$6),IF($N7="CRÍTICA","C","P"),"")) | U7: =IF(OR($D7="",$E7=""),"",IF(AND($D7<=U$6+6,$E7>=U$6),IF($N7="CRÍTICA","C","P"),"")) | V7: =IF(OR($D7="",$E7=""),"",IF(AND($D7<=V$6+6,$E7>=V$6),IF($N7="CRÍTICA","C","P"),"")) | W7: =IF(OR($D7="",$E7=""),"",IF(AND($D7<=W$6+6,$E7>=W$6),IF($N7="CRÍTICA","C","P"),"")) | X7: =IF(OR($D7="",$E7=""),"",IF(AND($D7<=X$6+6,$E7>=X$6),IF($N7="CRÍTICA","C","P"),"")) -> P | ... BR7: =IF(OR($D7="",$E7=""),"",IF(AND($D7<=BR$6+6,$E7>=BR$6),IF($N7="CRÍTICA","C","P"),"")) | BT7: =_xlfn.MINIFS($G$74:$G$103,$D$74:$D$103,$A7) -> 46314 | BU7: =_xlfn.MAXIFS($H$74:$H$103,$D$74:$D$103,$A7) -> 46604 | BV7: Contrato | BW7: 342 | BX7: =IF(E7="","",IF(COUNTIF($G8:$G$28,$A7)+COUNTIF($H8:$H$28,$A7)+COUNTIF($I8:$I$28,$A7)=0,_xlfn.MAXIFS($E$7:$E$27,$BW$7:$BW$27,$BW7),MIN(IF(COUNTIF($G8:$G$28,$A7)>0,_xlfn.MINIFS($BY8:$BY$28,$G8:$G$28,$A7),99999999),IF(COUNTIF($H8:$H$28,$A7)>0,_xlfn.MINIFS($BY8:$BY$28,$H8:$H$28,$A7),99999999),IF(COUNTIF($I8:$I$28,$A7)>0,_xlfn.MINIFS($BY8:$BY$28,$I8:$I$28,$A7),99999999))-1)) -> 46626 | BY7: =IF(BX7="","",BX7-F7+1) -> 46336 | BZ7: =IF(AND(D7<>"",D7>DATA_GESTAO),D7+ROW()/1000000,"") -> 46314 | CA7: =SUMPRODUCT(($BW$7:$BW$27=$BW7)*($G$7:$I$27<>"")) -> 0
A8: 342-02 | B8: 342 | C8: ADMINISTRAÇÃO LOCAL | D8: =IF(BT8="","",MAX(BT8,IF($G8="",0,_xlfn.MAXIFS($E$6:$E7,$A$6:$A7,$G8)+1),IF($H8="",0,_xlfn.MAXIFS($E$6:$E7,$A$6:$A7,$H8)+1),IF($I8="",0,_xlfn.MAXIFS($E$6:$E7,$A$6:$A7,$I8)+1))) -> 46314 | E8: =IF(D8="","",D8+F8-1) -> 46604 | F8: =IF(OR(BT8="",BU8=""),"",BU8-BT8+1) -> 291 | K8: =$P34 -> 479911 | L8: pendente | M8: =IF(OR(BX8="",E8=""),"",BX8-E8) -> 22 | N8: =IF(M8="","",IF(CA8=0,"sem rede",IF(M8<=0,"CRÍTICA",""))) -> sem rede | O8: =IF(OR(J8="",K8=""),"",J8*K8) | P8: =IF(OR(BT8="",BU8=""),"sem data",IF(OR(AND(G8<>"",COUNTIF($A$7:$A$27,G8)=0),AND(H8<>"",COUNTIF($A$7:$A$27,H8)=0),AND(I8<>"",COUNTIF($A$7:$A$27,I8)=0)),"predecessora inexistente",IF(OR(AND(G8<>"",COUNTIF($A$6:$A7,G8)=0),AND(H8<>"",COUNTIF($A$6:$A7,H8)=0),AND(I8<>"",COUNTIF($A$6:$A7,I8)=0)),"predecessora abaixo da tarefa","ok"))) -> ok | Q8: =IF(OR($D8="",$E8=""),"",IF(AND($D8<=Q$6+6,$E8>=Q$6),IF($N8="CRÍTICA","C","P"),"")) | R8: =IF(OR($D8="",$E8=""),"",IF(AND($D8<=R$6+6,$E8>=R$6),IF($N8="CRÍTICA","C","P"),"")) | S8: =IF(OR($D8="",$E8=""),"",IF(AND($D8<=S$6+6,$E8>=S$6),IF($N8="CRÍTICA","C","P"),"")) | T8: =IF(OR($D8="",$E8=""),"",IF(AND($D8<=T$6+6,$E8>=T$6),IF($N8="CRÍTICA","C","P"),"")) | U8: =IF(OR($D8="",$E8=""),"",IF(AND($D8<=U$6+6,$E8>=U$6),IF($N8="CRÍTICA","C","P"),"")) | V8: =IF(OR($D8="",$E8=""),"",IF(AND($D8<=V$6+6,$E8>=V$6),IF($N8="CRÍTICA","C","P"),"")) | W8: =IF(OR($D8="",$E8=""),"",IF(AND($D8<=W$6+6,$E8>=W$6),IF($N8="CRÍTICA","C","P"),"")) | X8: =IF(OR($D8="",$E8=""),"",IF(AND($D8<=X$6+6,$E8>=X$6),IF($N8="CRÍTICA","C","P"),"")) -> P | ... BR8: =IF(OR($D8="",$E8=""),"",IF(AND($D8<=BR$6+6,$E8>=BR$6),IF($N8="CRÍTICA","C","P"),"")) | BT8: =_xlfn.MINIFS($G$74:$G$103,$D$74:$D$103,$A8) -> 46314 | BU8: =_xlfn.MAXIFS($H$74:$H$103,$D$74:$D$103,$A8) -> 46604 | BV8: Contrato | BW8: 342 | BX8: =IF(E8="","",IF(COUNTIF($G9:$G$28,$A8)+COUNTIF($H9:$H$28,$A8)+COUNTIF($I9:$I$28,$A8)=0,_xlfn.MAXIFS($E$7:$E$27,$BW$7:$BW$27,$BW8),MIN(IF(COUNTIF($G9:$G$28,$A8)>0,_xlfn.MINIFS($BY9:$BY$28,$G9:$G$28,$A8),99999999),IF(COUNTIF($H9:$H$28,$A8)>0,_xlfn.MINIFS($BY9:$BY$28,$H9:$H$28,$A8),99999999),IF(COUNTIF($I9:$I$28,$A8)>0,_xlfn.MINIFS($BY9:$BY$28,$I9:$I$28,$A8),99999999))-1)) -> 46626 | BY8: =IF(BX8="","",BX8-F8+1) -> 46336 | BZ8: =IF(AND(D8<>"",D8>DATA_GESTAO),D8+ROW()/1000000,"") -> 46314 | CA8: =SUMPRODUCT(($BW$7:$BW$27=$BW8)*($G$7:$I$27<>"")) -> 0
A9: 342-03 | B9: 342 | C9: TERRAPLANAGEM E DESVIO DE TUBULAÇÃO | D9: =IF(BT9="","",MAX(BT9,IF($G9="",0,_xlfn.MAXIFS($E$6:$E8,$A$6:$A8,$G9)+1),IF($H9="",0,_xlfn.MAXIFS($E$6:$E8,$A$6:$A8,$H9)+1),IF($I9="",0,_xlfn.MAXIFS($E$6:$E8,$A$6:$A8,$I9)+1))) -> 46314 | E9: =IF(D9="","",D9+F9-1) -> 46325 | F9: =IF(OR(BT9="",BU9=""),"",BU9-BT9+1) -> 12 | K9: =$P35 -> 131545.55 | L9: pendente | M9: =IF(OR(BX9="",E9=""),"",BX9-E9) -> 301 | N9: =IF(M9="","",IF(CA9=0,"sem rede",IF(M9<=0,"CRÍTICA",""))) -> sem rede | O9: =IF(OR(J9="",K9=""),"",J9*K9) | P9: =IF(OR(BT9="",BU9=""),"sem data",IF(OR(AND(G9<>"",COUNTIF($A$7:$A$27,G9)=0),AND(H9<>"",COUNTIF($A$7:$A$27,H9)=0),AND(I9<>"",COUNTIF($A$7:$A$27,I9)=0)),"predecessora inexistente",IF(OR(AND(G9<>"",COUNTIF($A$6:$A8,G9)=0),AND(H9<>"",COUNTIF($A$6:$A8,H9)=0),AND(I9<>"",COUNTIF($A$6:$A8,I9)=0)),"predecessora abaixo da tarefa","ok"))) -> ok | Q9: =IF(OR($D9="",$E9=""),"",IF(AND($D9<=Q$6+6,$E9>=Q$6),IF($N9="CRÍTICA","C","P"),"")) | R9: =IF(OR($D9="",$E9=""),"",IF(AND($D9<=R$6+6,$E9>=R$6),IF($N9="CRÍTICA","C","P"),"")) | S9: =IF(OR($D9="",$E9=""),"",IF(AND($D9<=S$6+6,$E9>=S$6),IF($N9="CRÍTICA","C","P"),"")) | T9: =IF(OR($D9="",$E9=""),"",IF(AND($D9<=T$6+6,$E9>=T$6),IF($N9="CRÍTICA","C","P"),"")) | U9: =IF(OR($D9="",$E9=""),"",IF(AND($D9<=U$6+6,$E9>=U$6),IF($N9="CRÍTICA","C","P"),"")) | V9: =IF(OR($D9="",$E9=""),"",IF(AND($D9<=V$6+6,$E9>=V$6),IF($N9="CRÍTICA","C","P"),"")) | W9: =IF(OR($D9="",$E9=""),"",IF(AND($D9<=W$6+6,$E9>=W$6),IF($N9="CRÍTICA","C","P"),"")) | X9: =IF(OR($D9="",$E9=""),"",IF(AND($D9<=X$6+6,$E9>=X$6),IF($N9="CRÍTICA","C","P"),"")) -> P | ... BR9: =IF(OR($D9="",$E9=""),"",IF(AND($D9<=BR$6+6,$E9>=BR$6),IF($N9="CRÍTICA","C","P"),"")) | BT9: =_xlfn.MINIFS($G$74:$G$103,$D$74:$D$103,$A9) -> 46314 | BU9: =_xlfn.MAXIFS($H$74:$H$103,$D$74:$D$103,$A9) -> 46325 | BV9: Contrato | BW9: 342 | BX9: =IF(E9="","",IF(COUNTIF($G10:$G$28,$A9)+COUNTIF($H10:$H$28,$A9)+COUNTIF($I10:$I$28,$A9)=0,_xlfn.MAXIFS($E$7:$E$27,$BW$7:$BW$27,$BW9),MIN(IF(COUNTIF($G10:$G$28,$A9)>0,_xlfn.MINIFS($BY10:$BY$28,$G10:$G$28,$A9),99999999),IF(COUNTIF($H10:$H$28,$A9)>0,_xlfn.MINIFS($BY10:$BY$28,$H10:$H$28,$A9),99999999),IF(COUNTIF($I10:$I$28,$A9)>0,_xlfn.MINIFS($BY10:$BY$28,$I10:$I$28,$A9),99999999))-1)) -> 46626 | BY9: =IF(BX9="","",BX9-F9+1) -> 46615 | BZ9: =IF(AND(D9<>"",D9>DATA_GESTAO),D9+ROW()/1000000,"") -> 46314 | CA9: =SUMPRODUCT(($BW$7:$BW$27=$BW9)*($G$7:$I$27<>"")) -> 0
A10: 342-04 | B10: 342 | C10: INTERLIGAÇÕES ETA × UTR | D10: =IF(BT10="","",MAX(BT10,IF($G10="",0,_xlfn.MAXIFS($E$6:$E9,$A$6:$A9,$G10)+1),IF($H10="",0,_xlfn.MAXIFS($E$6:$E9,$A$6:$A9,$H10)+1),IF($I10="",0,_xlfn.MAXIFS($E$6:$E9,$A$6:$A9,$I10)+1))) -> 46358 | E10: =IF(D10="","",D10+F10-1) -> 46380 | F10: =IF(OR(BT10="",BU10=""),"",BU10-BT10+1) -> 23 | K10: =$P36 -> 334559.95 | L10: pendente | M10: =IF(OR(BX10="",E10=""),"",BX10-E10) -> 246 | N10: =IF(M10="","",IF(CA10=0,"sem rede",IF(M10<=0,"CRÍTICA",""))) -> sem rede | O10: =IF(OR(J10="",K10=""),"",J10*K10) | P10: =IF(OR(BT10="",BU10=""),"sem data",IF(OR(AND(G10<>"",COUNTIF($A$7:$A$27,G10)=0),AND(H10<>"",COUNTIF($A$7:$A$27,H10)=0),AND(I10<>"",COUNTIF($A$7:$A$27,I10)=0)),"predecessora inexistente",IF(OR(AND(G10<>"",COUNTIF($A$6:$A9,G10)=0),AND(H10<>"",COUNTIF($A$6:$A9,H10)=0),AND(I10<>"",COUNTIF($A$6:$A9,I10)=0)),"predecessora abaixo da tarefa","ok"))) -> ok | Q10: =IF(OR($D10="",$E10=""),"",IF(AND($D10<=Q$6+6,$E10>=Q$6),IF($N10="CRÍTICA","C","P"),"")) | R10: =IF(OR($D10="",$E10=""),"",IF(AND($D10<=R$6+6,$E10>=R$6),IF($N10="CRÍTICA","C","P"),"")) | S10: =IF(OR($D10="",$E10=""),"",IF(AND($D10<=S$6+6,$E10>=S$6),IF($N10="CRÍTICA","C","P"),"")) | T10: =IF(OR($D10="",$E10=""),"",IF(AND($D10<=T$6+6,$E10>=T$6),IF($N10="CRÍTICA","C","P"),"")) | U10: =IF(OR($D10="",$E10=""),"",IF(AND($D10<=U$6+6,$E10>=U$6),IF($N10="CRÍTICA","C","P"),"")) | V10: =IF(OR($D10="",$E10=""),"",IF(AND($D10<=V$6+6,$E10>=V$6),IF($N10="CRÍTICA","C","P"),"")) | W10: =IF(OR($D10="",$E10=""),"",IF(AND($D10<=W$6+6,$E10>=W$6),IF($N10="CRÍTICA","C","P"),"")) | X10: =IF(OR($D10="",$E10=""),"",IF(AND($D10<=X$6+6,$E10>=X$6),IF($N10="CRÍTICA","C","P"),"")) | ... BR10: =IF(OR($D10="",$E10=""),"",IF(AND($D10<=BR$6+6,$E10>=BR$6),IF($N10="CRÍTICA","C","P"),"")) | BT10: =_xlfn.MINIFS($G$74:$G$103,$D$74:$D$103,$A10) -> 46358 | BU10: =_xlfn.MAXIFS($H$74:$H$103,$D$74:$D$103,$A10) -> 46380 | BV10: Contrato | BW10: 342 | BX10: =IF(E10="","",IF(COUNTIF($G11:$G$28,$A10)+COUNTIF($H11:$H$28,$A10)+COUNTIF($I11:$I$28,$A10)=0,_xlfn.MAXIFS($E$7:$E$27,$BW$7:$BW$27,$BW10),MIN(IF(COUNTIF($G11:$G$28,$A10)>0,_xlfn.MINIFS($BY11:$BY$28,$G11:$G$28,$A10),99999999),IF(COUNTIF($H11:$H$28,$A10)>0,_xlfn.MINIFS($BY11:$BY$28,$H11:$H$28,$A10),99999999),IF(COUNTIF($I11:$I$28,$A10)>0,_xlfn.MINIFS($BY11:$BY$28,$I11:$I$28,$A10),99999999))-1)) -> 46626 | BY10: =IF(BX10="","",BX10-F10+1) -> 46604 | BZ10: =IF(AND(D10<>"",D10>DATA_GESTAO),D10+ROW()/1000000,"") -> 46358 | CA10: =SUMPRODUCT(($BW$7:$BW$27=$BW10)*($G$7:$I$27<>"")) -> 0
A11: 342-05 | B11: 342 | C11: INTERLIGAÇÕES LINHA DE RECALQUE UTR × ETA | D11: =IF(BT11="","",MAX(BT11,IF($G11="",0,_xlfn.MAXIFS($E$6:$E10,$A$6:$A10,$G11)+1),IF($H11="",0,_xlfn.MAXIFS($E$6:$E10,$A$6:$A10,$H11)+1),IF($I11="",0,_xlfn.MAXIFS($E$6:$E10,$A$6:$A10,$I11)+1))) -> 46370 | E11: =IF(D11="","",D11+F11-1) -> 46387 | F11: =IF(OR(BT11="",BU11=""),"",BU11-BT11+1) -> 18 | K11: =$P37 -> 54857.68 | L11: pendente | M11: =IF(OR(BX11="",E11=""),"",BX11-E11) -> 239 | N11: =IF(M11="","",IF(CA11=0,"sem rede",IF(M11<=0,"CRÍTICA",""))) -> sem rede | O11: =IF(OR(J11="",K11=""),"",J11*K11) | P11: =IF(OR(BT11="",BU11=""),"sem data",IF(OR(AND(G11<>"",COUNTIF($A$7:$A$27,G11)=0),AND(H11<>"",COUNTIF($A$7:$A$27,H11)=0),AND(I11<>"",COUNTIF($A$7:$A$27,I11)=0)),"predecessora inexistente",IF(OR(AND(G11<>"",COUNTIF($A$6:$A10,G11)=0),AND(H11<>"",COUNTIF($A$6:$A10,H11)=0),AND(I11<>"",COUNTIF($A$6:$A10,I11)=0)),"predecessora abaixo da tarefa","ok"))) -> ok | Q11: =IF(OR($D11="",$E11=""),"",IF(AND($D11<=Q$6+6,$E11>=Q$6),IF($N11="CRÍTICA","C","P"),"")) | R11: =IF(OR($D11="",$E11=""),"",IF(AND($D11<=R$6+6,$E11>=R$6),IF($N11="CRÍTICA","C","P"),"")) | S11: =IF(OR($D11="",$E11=""),"",IF(AND($D11<=S$6+6,$E11>=S$6),IF($N11="CRÍTICA","C","P"),"")) | T11: =IF(OR($D11="",$E11=""),"",IF(AND($D11<=T$6+6,$E11>=T$6),IF($N11="CRÍTICA","C","P"),"")) | U11: =IF(OR($D11="",$E11=""),"",IF(AND($D11<=U$6+6,$E11>=U$6),IF($N11="CRÍTICA","C","P"),"")) | V11: =IF(OR($D11="",$E11=""),"",IF(AND($D11<=V$6+6,$E11>=V$6),IF($N11="CRÍTICA","C","P"),"")) | W11: =IF(OR($D11="",$E11=""),"",IF(AND($D11<=W$6+6,$E11>=W$6),IF($N11="CRÍTICA","C","P"),"")) | X11: =IF(OR($D11="",$E11=""),"",IF(AND($D11<=X$6+6,$E11>=X$6),IF($N11="CRÍTICA","C","P"),"")) | ... BR11: =IF(OR($D11="",$E11=""),"",IF(AND($D11<=BR$6+6,$E11>=BR$6),IF($N11="CRÍTICA","C","P"),"")) | BT11: =_xlfn.MINIFS($G$74:$G$103,$D$74:$D$103,$A11) -> 46370 | BU11: =_xlfn.MAXIFS($H$74:$H$103,$D$74:$D$103,$A11) -> 46387 | BV11: Contrato | BW11: 342 | BX11: =IF(E11="","",IF(COUNTIF($G12:$G$28,$A11)+COUNTIF($H12:$H$28,$A11)+COUNTIF($I12:$I$28,$A11)=0,_xlfn.MAXIFS($E$7:$E$27,$BW$7:$BW$27,$BW11),MIN(IF(COUNTIF($G12:$G$28,$A11)>0,_xlfn.MINIFS($BY12:$BY$28,$G12:$G$28,$A11),99999999),IF(COUNTIF($H12:$H$28,$A11)>0,_xlfn.MINIFS($BY12:$BY$28,$H12:$H$28,$A11),99999999),IF(COUNTIF($I12:$I$28,$A11)>0,_xlfn.MINIFS($BY12:$BY$28,$I12:$I$28,$A11),99999999))-1)) -> 46626 | BY11: =IF(BX11="","",BX11-F11+1) -> 46609 | BZ11: =IF(AND(D11<>"",D11>DATA_GESTAO),D11+ROW()/1000000,"") -> 46370 | CA11: =SUMPRODUCT(($BW$7:$BW$27=$BW11)*($G$7:$I$27<>"")) -> 0
A12: 342-06 | B12: 342 | C12: DRENAGENS, ESGOTAMENTO E CAIXA DE CHEGADA | D12: =IF(BT12="","",MAX(BT12,IF($G12="",0,_xlfn.MAXIFS($E$6:$E11,$A$6:$A11,$G12)+1),IF($H12="",0,_xlfn.MAXIFS($E$6:$E11,$A$6:$A11,$H12)+1),IF($I12="",0,_xlfn.MAXIFS($E$6:$E11,$A$6:$A11,$I12)+1))) -> 46349 | E12: =IF(D12="","",D12+F12-1) -> 46366 | F12: =IF(OR(BT12="",BU12=""),"",BU12-BT12+1) -> 18 | K12: =$P38 -> 72003.88 | L12: pendente | M12: =IF(OR(BX12="",E12=""),"",BX12-E12) -> 260 | N12: =IF(M12="","",IF(CA12=0,"sem rede",IF(M12<=0,"CRÍTICA",""))) -> sem rede | O12: =IF(OR(J12="",K12=""),"",J12*K12) | P12: =IF(OR(BT12="",BU12=""),"sem data",IF(OR(AND(G12<>"",COUNTIF($A$7:$A$27,G12)=0),AND(H12<>"",COUNTIF($A$7:$A$27,H12)=0),AND(I12<>"",COUNTIF($A$7:$A$27,I12)=0)),"predecessora inexistente",IF(OR(AND(G12<>"",COUNTIF($A$6:$A11,G12)=0),AND(H12<>"",COUNTIF($A$6:$A11,H12)=0),AND(I12<>"",COUNTIF($A$6:$A11,I12)=0)),"predecessora abaixo da tarefa","ok"))) -> ok | Q12: =IF(OR($D12="",$E12=""),"",IF(AND($D12<=Q$6+6,$E12>=Q$6),IF($N12="CRÍTICA","C","P"),"")) | R12: =IF(OR($D12="",$E12=""),"",IF(AND($D12<=R$6+6,$E12>=R$6),IF($N12="CRÍTICA","C","P"),"")) | S12: =IF(OR($D12="",$E12=""),"",IF(AND($D12<=S$6+6,$E12>=S$6),IF($N12="CRÍTICA","C","P"),"")) | T12: =IF(OR($D12="",$E12=""),"",IF(AND($D12<=T$6+6,$E12>=T$6),IF($N12="CRÍTICA","C","P"),"")) | U12: =IF(OR($D12="",$E12=""),"",IF(AND($D12<=U$6+6,$E12>=U$6),IF($N12="CRÍTICA","C","P"),"")) | V12: =IF(OR($D12="",$E12=""),"",IF(AND($D12<=V$6+6,$E12>=V$6),IF($N12="CRÍTICA","C","P"),"")) | W12: =IF(OR($D12="",$E12=""),"",IF(AND($D12<=W$6+6,$E12>=W$6),IF($N12="CRÍTICA","C","P"),"")) | X12: =IF(OR($D12="",$E12=""),"",IF(AND($D12<=X$6+6,$E12>=X$6),IF($N12="CRÍTICA","C","P"),"")) | ... BR12: =IF(OR($D12="",$E12=""),"",IF(AND($D12<=BR$6+6,$E12>=BR$6),IF($N12="CRÍTICA","C","P"),"")) | BT12: =_xlfn.MINIFS($G$74:$G$103,$D$74:$D$103,$A12) -> 46349 | BU12: =_xlfn.MAXIFS($H$74:$H$103,$D$74:$D$103,$A12) -> 46366 | BV12: Contrato | BW12: 342 | BX12: =IF(E12="","",IF(COUNTIF($G13:$G$28,$A12)+COUNTIF($H13:$H$28,$A12)+COUNTIF($I13:$I$28,$A12)=0,_xlfn.MAXIFS($E$7:$E$27,$BW$7:$BW$27,$BW12),MIN(IF(COUNTIF($G13:$G$28,$A12)>0,_xlfn.MINIFS($BY13:$BY$28,$G13:$G$28,$A12),99999999),IF(COUNTIF($H13:$H$28,$A12)>0,_xlfn.MINIFS($BY13:$BY$28,$H13:$H$28,$A12),99999999),IF(COUNTIF($I13:$I$28,$A12)>0,_xlfn.MINIFS($BY13:$BY$28,$I13:$I$28,$A12),99999999))-1)) -> 46626 | BY12: =IF(BX12="","",BX12-F12+1) -> 46609 | BZ12: =IF(AND(D12<>"",D12>DATA_GESTAO),D12+ROW()/1000000,"") -> 46349 | CA12: =SUMPRODUCT(($BW$7:$BW$27=$BW12)*($G$7:$I$27<>"")) -> 0
A13: 342-07 | B13: 342 | C13: TANQUE DE LODO | D13: =IF(BT13="","",MAX(BT13,IF($G13="",0,_xlfn.MAXIFS($E$6:$E12,$A$6:$A12,$G13)+1),IF($H13="",0,_xlfn.MAXIFS($E$6:$E12,$A$6:$A12,$H13)+1),IF($I13="",0,_xlfn.MAXIFS($E$6:$E12,$A$6:$A12,$I13)+1))) -> 46329 | E13: =IF(D13="","",D13+F13-1) -> 46518 | F13: =IF(OR(BT13="",BU13=""),"",BU13-BT13+1) -> 190 | K13: =$P39 -> 1180517.8 | L13: pendente | M13: =IF(OR(BX13="",E13=""),"",BX13-E13) -> 108 | N13: =IF(M13="","",IF(CA13=0,"sem rede",IF(M13<=0,"CRÍTICA",""))) -> sem rede | O13: =IF(OR(J13="",K13=""),"",J13*K13) | P13: =IF(OR(BT13="",BU13=""),"sem data",IF(OR(AND(G13<>"",COUNTIF($A$7:$A$27,G13)=0),AND(H13<>"",COUNTIF($A$7:$A$27,H13)=0),AND(I13<>"",COUNTIF($A$7:$A$27,I13)=0)),"predecessora inexistente",IF(OR(AND(G13<>"",COUNTIF($A$6:$A12,G13)=0),AND(H13<>"",COUNTIF($A$6:$A12,H13)=0),AND(I13<>"",COUNTIF($A$6:$A12,I13)=0)),"predecessora abaixo da tarefa","ok"))) -> ok | Q13: =IF(OR($D13="",$E13=""),"",IF(AND($D13<=Q$6+6,$E13>=Q$6),IF($N13="CRÍTICA","C","P"),"")) | R13: =IF(OR($D13="",$E13=""),"",IF(AND($D13<=R$6+6,$E13>=R$6),IF($N13="CRÍTICA","C","P"),"")) | S13: =IF(OR($D13="",$E13=""),"",IF(AND($D13<=S$6+6,$E13>=S$6),IF($N13="CRÍTICA","C","P"),"")) | T13: =IF(OR($D13="",$E13=""),"",IF(AND($D13<=T$6+6,$E13>=T$6),IF($N13="CRÍTICA","C","P"),"")) | U13: =IF(OR($D13="",$E13=""),"",IF(AND($D13<=U$6+6,$E13>=U$6),IF($N13="CRÍTICA","C","P"),"")) | V13: =IF(OR($D13="",$E13=""),"",IF(AND($D13<=V$6+6,$E13>=V$6),IF($N13="CRÍTICA","C","P"),"")) | W13: =IF(OR($D13="",$E13=""),"",IF(AND($D13<=W$6+6,$E13>=W$6),IF($N13="CRÍTICA","C","P"),"")) | X13: =IF(OR($D13="",$E13=""),"",IF(AND($D13<=X$6+6,$E13>=X$6),IF($N13="CRÍTICA","C","P"),"")) | ... BR13: =IF(OR($D13="",$E13=""),"",IF(AND($D13<=BR$6+6,$E13>=BR$6),IF($N13="CRÍTICA","C","P"),"")) | BT13: =_xlfn.MINIFS($G$74:$G$103,$D$74:$D$103,$A13) -> 46329 | BU13: =_xlfn.MAXIFS($H$74:$H$103,$D$74:$D$103,$A13) -> 46518 | BV13: Contrato | BW13: 342 | BX13: =IF(E13="","",IF(COUNTIF($G14:$G$28,$A13)+COUNTIF($H14:$H$28,$A13)+COUNTIF($I14:$I$28,$A13)=0,_xlfn.MAXIFS($E$7:$E$27,$BW$7:$BW$27,$BW13),MIN(IF(COUNTIF($G14:$G$28,$A13)>0,_xlfn.MINIFS($BY14:$BY$28,$G14:$G$28,$A13),99999999),IF(COUNTIF($H14:$H$28,$A13)>0,_xlfn.MINIFS($BY14:$BY$28,$H14:$H$28,$A13),99999999),IF(COUNTIF($I14:$I$28,$A13)>0,_xlfn.MINIFS($BY14:$BY$28,$I14:$I$28,$A13),99999999))-1)) -> 46626 | BY13: =IF(BX13="","",BX13-F13+1) -> 46437 | BZ13: =IF(AND(D13<>"",D13>DATA_GESTAO),D13+ROW()/1000000,"") -> 46329 | CA13: =SUMPRODUCT(($BW$7:$BW$27=$BW13)*($G$7:$I$27<>"")) -> 0
A14: 342-08 | B14: 342 | C14: ESTAÇÃO ELEVATÓRIA DE RECIRCULAÇÃO DE LODO | D14: =IF(BT14="","",MAX(BT14,IF($G14="",0,_xlfn.MAXIFS($E$6:$E13,$A$6:$A13,$G14)+1),IF($H14="",0,_xlfn.MAXIFS($E$6:$E13,$A$6:$A13,$H14)+1),IF($I14="",0,_xlfn.MAXIFS($E$6:$E13,$A$6:$A13,$I14)+1))) -> 46408 | E14: =IF(D14="","",D14+F14-1) -> 46549 | F14: =IF(OR(BT14="",BU14=""),"",BU14-BT14+1) -> 142 | K14: =$P40 -> 530787.26 | L14: pendente | M14: =IF(OR(BX14="",E14=""),"",BX14-E14) -> 77 | N14: =IF(M14="","",IF(CA14=0,"sem rede",IF(M14<=0,"CRÍTICA",""))) -> sem rede | O14: =IF(OR(J14="",K14=""),"",J14*K14) | P14: =IF(OR(BT14="",BU14=""),"sem data",IF(OR(AND(G14<>"",COUNTIF($A$7:$A$27,G14)=0),AND(H14<>"",COUNTIF($A$7:$A$27,H14)=0),AND(I14<>"",COUNTIF($A$7:$A$27,I14)=0)),"predecessora inexistente",IF(OR(AND(G14<>"",COUNTIF($A$6:$A13,G14)=0),AND(H14<>"",COUNTIF($A$6:$A13,H14)=0),AND(I14<>"",COUNTIF($A$6:$A13,I14)=0)),"predecessora abaixo da tarefa","ok"))) -> ok | Q14: =IF(OR($D14="",$E14=""),"",IF(AND($D14<=Q$6+6,$E14>=Q$6),IF($N14="CRÍTICA","C","P"),"")) | R14: =IF(OR($D14="",$E14=""),"",IF(AND($D14<=R$6+6,$E14>=R$6),IF($N14="CRÍTICA","C","P"),"")) | S14: =IF(OR($D14="",$E14=""),"",IF(AND($D14<=S$6+6,$E14>=S$6),IF($N14="CRÍTICA","C","P"),"")) | T14: =IF(OR($D14="",$E14=""),"",IF(AND($D14<=T$6+6,$E14>=T$6),IF($N14="CRÍTICA","C","P"),"")) | U14: =IF(OR($D14="",$E14=""),"",IF(AND($D14<=U$6+6,$E14>=U$6),IF($N14="CRÍTICA","C","P"),"")) | V14: =IF(OR($D14="",$E14=""),"",IF(AND($D14<=V$6+6,$E14>=V$6),IF($N14="CRÍTICA","C","P"),"")) | W14: =IF(OR($D14="",$E14=""),"",IF(AND($D14<=W$6+6,$E14>=W$6),IF($N14="CRÍTICA","C","P"),"")) | X14: =IF(OR($D14="",$E14=""),"",IF(AND($D14<=X$6+6,$E14>=X$6),IF($N14="CRÍTICA","C","P"),"")) | ... BR14: =IF(OR($D14="",$E14=""),"",IF(AND($D14<=BR$6+6,$E14>=BR$6),IF($N14="CRÍTICA","C","P"),"")) | BT14: =_xlfn.MINIFS($G$74:$G$103,$D$74:$D$103,$A14) -> 46408 | BU14: =_xlfn.MAXIFS($H$74:$H$103,$D$74:$D$103,$A14) -> 46549 | BV14: Contrato | BW14: 342 | BX14: =IF(E14="","",IF(COUNTIF($G15:$G$28,$A14)+COUNTIF($H15:$H$28,$A14)+COUNTIF($I15:$I$28,$A14)=0,_xlfn.MAXIFS($E$7:$E$27,$BW$7:$BW$27,$BW14),MIN(IF(COUNTIF($G15:$G$28,$A14)>0,_xlfn.MINIFS($BY15:$BY$28,$G15:$G$28,$A14),99999999),IF(COUNTIF($H15:$H$28,$A14)>0,_xlfn.MINIFS($BY15:$BY$28,$H15:$H$28,$A14),99999999),IF(COUNTIF($I15:$I$28,$A14)>0,_xlfn.MINIFS($BY15:$BY$28,$I15:$I$28,$A14),99999999))-1)) -> 46626 | BY14: =IF(BX14="","",BX14-F14+1) -> 46485 | BZ14: =IF(AND(D14<>"",D14>DATA_GESTAO),D14+ROW()/1000000,"") -> 46408 | CA14: =SUMPRODUCT(($BW$7:$BW$27=$BW14)*($G$7:$I$27<>"")) -> 0
A15: 342-09 | B15: 342 | C15: URBANIZAÇÃO, CANALETAS, CAIXAS E SERVIÇOS COMPLEMENTARES | D15: =IF(BT15="","",MAX(BT15,IF($G15="",0,_xlfn.MAXIFS($E$6:$E14,$A$6:$A14,$G15)+1),IF($H15="",0,_xlfn.MAXIFS($E$6:$E14,$A$6:$A14,$H15)+1),IF($I15="",0,_xlfn.MAXIFS($E$6:$E14,$A$6:$A14,$I15)+1))) -> 46526 | E15: =IF(D15="","",D15+F15-1) -> 46589 | F15: =IF(OR(BT15="",BU15=""),"",BU15-BT15+1) -> 64 | K15: =$P41 -> 218637.74 | L15: pendente | M15: =IF(OR(BX15="",E15=""),"",BX15-E15) -> 37 | N15: =IF(M15="","",IF(CA15=0,"sem rede",IF(M15<=0,"CRÍTICA",""))) -> sem rede | O15: =IF(OR(J15="",K15=""),"",J15*K15) | P15: =IF(OR(BT15="",BU15=""),"sem data",IF(OR(AND(G15<>"",COUNTIF($A$7:$A$27,G15)=0),AND(H15<>"",COUNTIF($A$7:$A$27,H15)=0),AND(I15<>"",COUNTIF($A$7:$A$27,I15)=0)),"predecessora inexistente",IF(OR(AND(G15<>"",COUNTIF($A$6:$A14,G15)=0),AND(H15<>"",COUNTIF($A$6:$A14,H15)=0),AND(I15<>"",COUNTIF($A$6:$A14,I15)=0)),"predecessora abaixo da tarefa","ok"))) -> ok | Q15: =IF(OR($D15="",$E15=""),"",IF(AND($D15<=Q$6+6,$E15>=Q$6),IF($N15="CRÍTICA","C","P"),"")) | R15: =IF(OR($D15="",$E15=""),"",IF(AND($D15<=R$6+6,$E15>=R$6),IF($N15="CRÍTICA","C","P"),"")) | S15: =IF(OR($D15="",$E15=""),"",IF(AND($D15<=S$6+6,$E15>=S$6),IF($N15="CRÍTICA","C","P"),"")) | T15: =IF(OR($D15="",$E15=""),"",IF(AND($D15<=T$6+6,$E15>=T$6),IF($N15="CRÍTICA","C","P"),"")) | U15: =IF(OR($D15="",$E15=""),"",IF(AND($D15<=U$6+6,$E15>=U$6),IF($N15="CRÍTICA","C","P"),"")) | V15: =IF(OR($D15="",$E15=""),"",IF(AND($D15<=V$6+6,$E15>=V$6),IF($N15="CRÍTICA","C","P"),"")) | W15: =IF(OR($D15="",$E15=""),"",IF(AND($D15<=W$6+6,$E15>=W$6),IF($N15="CRÍTICA","C","P"),"")) | X15: =IF(OR($D15="",$E15=""),"",IF(AND($D15<=X$6+6,$E15>=X$6),IF($N15="CRÍTICA","C","P"),"")) | ... BR15: =IF(OR($D15="",$E15=""),"",IF(AND($D15<=BR$6+6,$E15>=BR$6),IF($N15="CRÍTICA","C","P"),"")) | BT15: =_xlfn.MINIFS($G$74:$G$103,$D$74:$D$103,$A15) -> 46526 | BU15: =_xlfn.MAXIFS($H$74:$H$103,$D$74:$D$103,$A15) -> 46589 | BV15: Contrato | BW15: 342 | BX15: =IF(E15="","",IF(COUNTIF($G16:$G$28,$A15)+COUNTIF($H16:$H$28,$A15)+COUNTIF($I16:$I$28,$A15)=0,_xlfn.MAXIFS($E$7:$E$27,$BW$7:$BW$27,$BW15),MIN(IF(COUNTIF($G16:$G$28,$A15)>0,_xlfn.MINIFS($BY16:$BY$28,$G16:$G$28,$A15),99999999),IF(COUNTIF($H16:$H$28,$A15)>0,_xlfn.MINIFS($BY16:$BY$28,$H16:$H$28,$A15),99999999),IF(COUNTIF($I16:$I$28,$A15)>0,_xlfn.MINIFS($BY16:$BY$28,$I16:$I$28,$A15),99999999))-1)) -> 46626 | BY15: =IF(BX15="","",BX15-F15+1) -> 46563 | BZ15: =IF(AND(D15<>"",D15>DATA_GESTAO),D15+ROW()/1000000,"") -> 46526 | CA15: =SUMPRODUCT(($BW$7:$BW$27=$BW15)*($G$7:$I$27<>"")) -> 0
A16: 342-10 | B16: 342 | C16: REDE DE DISTRIBUIÇÃO DE ENERGIA | D16: =IF(BT16="","",MAX(BT16,IF($G16="",0,_xlfn.MAXIFS($E$6:$E15,$A$6:$A15,$G16)+1),IF($H16="",0,_xlfn.MAXIFS($E$6:$E15,$A$6:$A15,$H16)+1),IF($I16="",0,_xlfn.MAXIFS($E$6:$E15,$A$6:$A15,$I16)+1))) -> 46433 | E16: =IF(D16="","",D16+F16-1) -> 46449 | F16: =IF(OR(BT16="",BU16=""),"",BU16-BT16+1) -> 17 | K16: =$P42 -> 104799.22 | L16: pendente | M16: =IF(OR(BX16="",E16=""),"",BX16-E16) -> 177 | N16: =IF(M16="","",IF(CA16=0,"sem rede",IF(M16<=0,"CRÍTICA",""))) -> sem rede | O16: =IF(OR(J16="",K16=""),"",J16*K16) | P16: =IF(OR(BT16="",BU16=""),"sem data",IF(OR(AND(G16<>"",COUNTIF($A$7:$A$27,G16)=0),AND(H16<>"",COUNTIF($A$7:$A$27,H16)=0),AND(I16<>"",COUNTIF($A$7:$A$27,I16)=0)),"predecessora inexistente",IF(OR(AND(G16<>"",COUNTIF($A$6:$A15,G16)=0),AND(H16<>"",COUNTIF($A$6:$A15,H16)=0),AND(I16<>"",COUNTIF($A$6:$A15,I16)=0)),"predecessora abaixo da tarefa","ok"))) -> ok | Q16: =IF(OR($D16="",$E16=""),"",IF(AND($D16<=Q$6+6,$E16>=Q$6),IF($N16="CRÍTICA","C","P"),"")) | R16: =IF(OR($D16="",$E16=""),"",IF(AND($D16<=R$6+6,$E16>=R$6),IF($N16="CRÍTICA","C","P"),"")) | S16: =IF(OR($D16="",$E16=""),"",IF(AND($D16<=S$6+6,$E16>=S$6),IF($N16="CRÍTICA","C","P"),"")) | T16: =IF(OR($D16="",$E16=""),"",IF(AND($D16<=T$6+6,$E16>=T$6),IF($N16="CRÍTICA","C","P"),"")) | U16: =IF(OR($D16="",$E16=""),"",IF(AND($D16<=U$6+6,$E16>=U$6),IF($N16="CRÍTICA","C","P"),"")) | V16: =IF(OR($D16="",$E16=""),"",IF(AND($D16<=V$6+6,$E16>=V$6),IF($N16="CRÍTICA","C","P"),"")) | W16: =IF(OR($D16="",$E16=""),"",IF(AND($D16<=W$6+6,$E16>=W$6),IF($N16="CRÍTICA","C","P"),"")) | X16: =IF(OR($D16="",$E16=""),"",IF(AND($D16<=X$6+6,$E16>=X$6),IF($N16="CRÍTICA","C","P"),"")) | ... BR16: =IF(OR($D16="",$E16=""),"",IF(AND($D16<=BR$6+6,$E16>=BR$6),IF($N16="CRÍTICA","C","P"),"")) | BT16: =_xlfn.MINIFS($G$74:$G$103,$D$74:$D$103,$A16) -> 46433 | BU16: =_xlfn.MAXIFS($H$74:$H$103,$D$74:$D$103,$A16) -> 46449 | BV16: Contrato | BW16: 342 | BX16: =IF(E16="","",IF(COUNTIF($G17:$G$28,$A16)+COUNTIF($H17:$H$28,$A16)+COUNTIF($I17:$I$28,$A16)=0,_xlfn.MAXIFS($E$7:$E$27,$BW$7:$BW$27,$BW16),MIN(IF(COUNTIF($G17:$G$28,$A16)>0,_xlfn.MINIFS($BY17:$BY$28,$G17:$G$28,$A16),99999999),IF(COUNTIF($H17:$H$28,$A16)>0,_xlfn.MINIFS($BY17:$BY$28,$H17:$H$28,$A16),99999999),IF(COUNTIF($I17:$I$28,$A16)>0,_xlfn.MINIFS($BY17:$BY$28,$I17:$I$28,$A16),99999999))-1)) -> 46626 | BY16: =IF(BX16="","",BX16-F16+1) -> 46610 | BZ16: =IF(AND(D16<>"",D16>DATA_GESTAO),D16+ROW()/1000000,"") -> 46433 | CA16: =SUMPRODUCT(($BW$7:$BW$27=$BW16)*($G$7:$I$27<>"")) -> 0
A17: 342-11 | B17: 342 | C17: PROJETOS EXECUTIVOS / AS BUILT | D17: =IF(BT17="","",MAX(BT17,IF($G17="",0,_xlfn.MAXIFS($E$6:$E16,$A$6:$A16,$G17)+1),IF($H17="",0,_xlfn.MAXIFS($E$6:$E16,$A$6:$A16,$H17)+1),IF($I17="",0,_xlfn.MAXIFS($E$6:$E16,$A$6:$A16,$I17)+1))) -> 46268 | E17: =IF(D17="","",D17+F17-1) -> 46626 | F17: =IF(OR(BT17="",BU17=""),"",BU17-BT17+1) -> 359 | K17: =$P43 -> 27956.66 | L17: pendente | M17: =IF(OR(BX17="",E17=""),"",BX17-E17) -> 0 | N17: =IF(M17="","",IF(CA17=0,"sem rede",IF(M17<=0,"CRÍTICA",""))) -> sem rede | O17: =IF(OR(J17="",K17=""),"",J17*K17) | P17: =IF(OR(BT17="",BU17=""),"sem data",IF(OR(AND(G17<>"",COUNTIF($A$7:$A$27,G17)=0),AND(H17<>"",COUNTIF($A$7:$A$27,H17)=0),AND(I17<>"",COUNTIF($A$7:$A$27,I17)=0)),"predecessora inexistente",IF(OR(AND(G17<>"",COUNTIF($A$6:$A16,G17)=0),AND(H17<>"",COUNTIF($A$6:$A16,H17)=0),AND(I17<>"",COUNTIF($A$6:$A16,I17)=0)),"predecessora abaixo da tarefa","ok"))) -> ok | Q17: =IF(OR($D17="",$E17=""),"",IF(AND($D17<=Q$6+6,$E17>=Q$6),IF($N17="CRÍTICA","C","P"),"")) -> P | R17: =IF(OR($D17="",$E17=""),"",IF(AND($D17<=R$6+6,$E17>=R$6),IF($N17="CRÍTICA","C","P"),"")) -> P | S17: =IF(OR($D17="",$E17=""),"",IF(AND($D17<=S$6+6,$E17>=S$6),IF($N17="CRÍTICA","C","P"),"")) -> P | T17: =IF(OR($D17="",$E17=""),"",IF(AND($D17<=T$6+6,$E17>=T$6),IF($N17="CRÍTICA","C","P"),"")) -> P | U17: =IF(OR($D17="",$E17=""),"",IF(AND($D17<=U$6+6,$E17>=U$6),IF($N17="CRÍTICA","C","P"),"")) -> P | V17: =IF(OR($D17="",$E17=""),"",IF(AND($D17<=V$6+6,$E17>=V$6),IF($N17="CRÍTICA","C","P"),"")) -> P | W17: =IF(OR($D17="",$E17=""),"",IF(AND($D17<=W$6+6,$E17>=W$6),IF($N17="CRÍTICA","C","P"),"")) -> P | X17: =IF(OR($D17="",$E17=""),"",IF(AND($D17<=X$6+6,$E17>=X$6),IF($N17="CRÍTICA","C","P"),"")) -> P | ... BR17: =IF(OR($D17="",$E17=""),"",IF(AND($D17<=BR$6+6,$E17>=BR$6),IF($N17="CRÍTICA","C","P"),"")) | BT17: =_xlfn.MINIFS($G$74:$G$103,$D$74:$D$103,$A17) -> 46268 | BU17: =_xlfn.MAXIFS($H$74:$H$103,$D$74:$D$103,$A17) -> 46626 | BV17: Contrato | BW17: 342 | BX17: =IF(E17="","",IF(COUNTIF($G18:$G$28,$A17)+COUNTIF($H18:$H$28,$A17)+COUNTIF($I18:$I$28,$A17)=0,_xlfn.MAXIFS($E$7:$E$27,$BW$7:$BW$27,$BW17),MIN(IF(COUNTIF($G18:$G$28,$A17)>0,_xlfn.MINIFS($BY18:$BY$28,$G18:$G$28,$A17),99999999),IF(COUNTIF($H18:$H$28,$A17)>0,_xlfn.MINIFS($BY18:$BY$28,$H18:$H$28,$A17),99999999),IF(COUNTIF($I18:$I$28,$A17)>0,_xlfn.MINIFS($BY18:$BY$28,$I18:$I$28,$A17),99999999))-1)) -> 46626 | BY17: =IF(BX17="","",BX17-F17+1) -> 46268 | BZ17: =IF(AND(D17<>"",D17>DATA_GESTAO),D17+ROW()/1000000,"") | CA17: =SUMPRODUCT(($BW$7:$BW$27=$BW17)*($G$7:$I$27<>"")) -> 0
A18: 343-01 | B18: 343 | C18: Canteiro de Obras | D18: =IF(BT18="","",MAX(BT18,IF($G18="",0,_xlfn.MAXIFS($E$6:$E17,$A$6:$A17,$G18)+1),IF($H18="",0,_xlfn.MAXIFS($E$6:$E17,$A$6:$A17,$H18)+1),IF($I18="",0,_xlfn.MAXIFS($E$6:$E17,$A$6:$A17,$I18)+1))) -> 46266 | E18: =IF(D18="","",D18+F18-1) -> 46538 | F18: =IF(OR(BT18="",BU18=""),"",BU18-BT18+1) -> 273 | K18: =$P44 -> 940360.23 | L18: pendente | M18: =IF(OR(BX18="",E18=""),"",BX18-E18) -> 0 | N18: =IF(M18="","",IF(CA18=0,"sem rede",IF(M18<=0,"CRÍTICA",""))) -> sem rede | O18: =IF(OR(J18="",K18=""),"",J18*K18) | P18: =IF(OR(BT18="",BU18=""),"sem data",IF(OR(AND(G18<>"",COUNTIF($A$7:$A$27,G18)=0),AND(H18<>"",COUNTIF($A$7:$A$27,H18)=0),AND(I18<>"",COUNTIF($A$7:$A$27,I18)=0)),"predecessora inexistente",IF(OR(AND(G18<>"",COUNTIF($A$6:$A17,G18)=0),AND(H18<>"",COUNTIF($A$6:$A17,H18)=0),AND(I18<>"",COUNTIF($A$6:$A17,I18)=0)),"predecessora abaixo da tarefa","ok"))) -> ok | Q18: =IF(OR($D18="",$E18=""),"",IF(AND($D18<=Q$6+6,$E18>=Q$6),IF($N18="CRÍTICA","C","P"),"")) -> P | R18: =IF(OR($D18="",$E18=""),"",IF(AND($D18<=R$6+6,$E18>=R$6),IF($N18="CRÍTICA","C","P"),"")) -> P | S18: =IF(OR($D18="",$E18=""),"",IF(AND($D18<=S$6+6,$E18>=S$6),IF($N18="CRÍTICA","C","P"),"")) -> P | T18: =IF(OR($D18="",$E18=""),"",IF(AND($D18<=T$6+6,$E18>=T$6),IF($N18="CRÍTICA","C","P"),"")) -> P | U18: =IF(OR($D18="",$E18=""),"",IF(AND($D18<=U$6+6,$E18>=U$6),IF($N18="CRÍTICA","C","P"),"")) -> P | V18: =IF(OR($D18="",$E18=""),"",IF(AND($D18<=V$6+6,$E18>=V$6),IF($N18="CRÍTICA","C","P"),"")) -> P | W18: =IF(OR($D18="",$E18=""),"",IF(AND($D18<=W$6+6,$E18>=W$6),IF($N18="CRÍTICA","C","P"),"")) -> P | X18: =IF(OR($D18="",$E18=""),"",IF(AND($D18<=X$6+6,$E18>=X$6),IF($N18="CRÍTICA","C","P"),"")) -> P | ... BR18: =IF(OR($D18="",$E18=""),"",IF(AND($D18<=BR$6+6,$E18>=BR$6),IF($N18="CRÍTICA","C","P"),"")) | BT18: =IF(SUM($D44:$O44)=0,"",_xlfn.MINIFS($D$32:$O$32,$D44:$O44,">0")) -> 46266 | BU18: =IF(BT18="","",EOMONTH(_xlfn.MAXIFS($D$32:$O$32,$D44:$O44,">0"),0)) -> 46538 | BV18: Contrato | BW18: 343 | BX18: =IF(E18="","",IF(COUNTIF($G19:$G$28,$A18)+COUNTIF($H19:$H$28,$A18)+COUNTIF($I19:$I$28,$A18)=0,_xlfn.MAXIFS($E$7:$E$27,$BW$7:$BW$27,$BW18),MIN(IF(COUNTIF($G19:$G$28,$A18)>0,_xlfn.MINIFS($BY19:$BY$28,$G19:$G$28,$A18),99999999),IF(COUNTIF($H19:$H$28,$A18)>0,_xlfn.MINIFS($BY19:$BY$28,$H19:$H$28,$A18),99999999),IF(COUNTIF($I19:$I$28,$A18)>0,_xlfn.MINIFS($BY19:$BY$28,$I19:$I$28,$A18),99999999))-1)) -> 46538 | BY18: =IF(BX18="","",BX18-F18+1) -> 46266 | BZ18: =IF(AND(D18<>"",D18>DATA_GESTAO),D18+ROW()/1000000,"") | CA18: =SUMPRODUCT(($BW$7:$BW$27=$BW18)*($G$7:$I$27<>"")) -> 0
A19: 343-02 | B19: 343 | C19: Subadutora | D19: =IF(BT19="","",MAX(BT19,IF($G19="",0,_xlfn.MAXIFS($E$6:$E18,$A$6:$A18,$G19)+1),IF($H19="",0,_xlfn.MAXIFS($E$6:$E18,$A$6:$A18,$H19)+1),IF($I19="",0,_xlfn.MAXIFS($E$6:$E18,$A$6:$A18,$I19)+1))) -> 46296 | E19: =IF(D19="","",D19+F19-1) -> 46507 | F19: =IF(OR(BT19="",BU19=""),"",BU19-BT19+1) -> 212 | K19: =$P45 -> 1674250.7 | L19: pendente | M19: =IF(OR(BX19="",E19=""),"",BX19-E19) -> 31 | N19: =IF(M19="","",IF(CA19=0,"sem rede",IF(M19<=0,"CRÍTICA",""))) -> sem rede | O19: =IF(OR(J19="",K19=""),"",J19*K19) | P19: =IF(OR(BT19="",BU19=""),"sem data",IF(OR(AND(G19<>"",COUNTIF($A$7:$A$27,G19)=0),AND(H19<>"",COUNTIF($A$7:$A$27,H19)=0),AND(I19<>"",COUNTIF($A$7:$A$27,I19)=0)),"predecessora inexistente",IF(OR(AND(G19<>"",COUNTIF($A$6:$A18,G19)=0),AND(H19<>"",COUNTIF($A$6:$A18,H19)=0),AND(I19<>"",COUNTIF($A$6:$A18,I19)=0)),"predecessora abaixo da tarefa","ok"))) -> ok | Q19: =IF(OR($D19="",$E19=""),"",IF(AND($D19<=Q$6+6,$E19>=Q$6),IF($N19="CRÍTICA","C","P"),"")) | R19: =IF(OR($D19="",$E19=""),"",IF(AND($D19<=R$6+6,$E19>=R$6),IF($N19="CRÍTICA","C","P"),"")) | S19: =IF(OR($D19="",$E19=""),"",IF(AND($D19<=S$6+6,$E19>=S$6),IF($N19="CRÍTICA","C","P"),"")) | T19: =IF(OR($D19="",$E19=""),"",IF(AND($D19<=T$6+6,$E19>=T$6),IF($N19="CRÍTICA","C","P"),"")) | U19: =IF(OR($D19="",$E19=""),"",IF(AND($D19<=U$6+6,$E19>=U$6),IF($N19="CRÍTICA","C","P"),"")) -> P | V19: =IF(OR($D19="",$E19=""),"",IF(AND($D19<=V$6+6,$E19>=V$6),IF($N19="CRÍTICA","C","P"),"")) -> P | W19: =IF(OR($D19="",$E19=""),"",IF(AND($D19<=W$6+6,$E19>=W$6),IF($N19="CRÍTICA","C","P"),"")) -> P | X19: =IF(OR($D19="",$E19=""),"",IF(AND($D19<=X$6+6,$E19>=X$6),IF($N19="CRÍTICA","C","P"),"")) -> P | ... BR19: =IF(OR($D19="",$E19=""),"",IF(AND($D19<=BR$6+6,$E19>=BR$6),IF($N19="CRÍTICA","C","P"),"")) | BT19: =IF(SUM($D45:$O45)=0,"",_xlfn.MINIFS($D$32:$O$32,$D45:$O45,">0")) -> 46296 | BU19: =IF(BT19="","",EOMONTH(_xlfn.MAXIFS($D$32:$O$32,$D45:$O45,">0"),0)) -> 46507 | BV19: Contrato | BW19: 343 | BX19: =IF(E19="","",IF(COUNTIF($G20:$G$28,$A19)+COUNTIF($H20:$H$28,$A19)+COUNTIF($I20:$I$28,$A19)=0,_xlfn.MAXIFS($E$7:$E$27,$BW$7:$BW$27,$BW19),MIN(IF(COUNTIF($G20:$G$28,$A19)>0,_xlfn.MINIFS($BY20:$BY$28,$G20:$G$28,$A19),99999999),IF(COUNTIF($H20:$H$28,$A19)>0,_xlfn.MINIFS($BY20:$BY$28,$H20:$H$28,$A19),99999999),IF(COUNTIF($I20:$I$28,$A19)>0,_xlfn.MINIFS($BY20:$BY$28,$I20:$I$28,$A19),99999999))-1)) -> 46538 | BY19: =IF(BX19="","",BX19-F19+1) -> 46327 | BZ19: =IF(AND(D19<>"",D19>DATA_GESTAO),D19+ROW()/1000000,"") | CA19: =SUMPRODUCT(($BW$7:$BW$27=$BW19)*($G$7:$I$27<>"")) -> 0
A20: 343-03 | B20: 343 | C20: Caixas e Interligações | D20: =IF(BT20="","",MAX(BT20,IF($G20="",0,_xlfn.MAXIFS($E$6:$E19,$A$6:$A19,$G20)+1),IF($H20="",0,_xlfn.MAXIFS($E$6:$E19,$A$6:$A19,$H20)+1),IF($I20="",0,_xlfn.MAXIFS($E$6:$E19,$A$6:$A19,$I20)+1))) -> 46296 | E20: =IF(D20="","",D20+F20-1) -> 46507 | F20: =IF(OR(BT20="",BU20=""),"",BU20-BT20+1) -> 212 | K20: =$P46 -> 290959.41 | L20: pendente | M20: =IF(OR(BX20="",E20=""),"",BX20-E20) -> 31 | N20: =IF(M20="","",IF(CA20=0,"sem rede",IF(M20<=0,"CRÍTICA",""))) -> sem rede | O20: =IF(OR(J20="",K20=""),"",J20*K20) | P20: =IF(OR(BT20="",BU20=""),"sem data",IF(OR(AND(G20<>"",COUNTIF($A$7:$A$27,G20)=0),AND(H20<>"",COUNTIF($A$7:$A$27,H20)=0),AND(I20<>"",COUNTIF($A$7:$A$27,I20)=0)),"predecessora inexistente",IF(OR(AND(G20<>"",COUNTIF($A$6:$A19,G20)=0),AND(H20<>"",COUNTIF($A$6:$A19,H20)=0),AND(I20<>"",COUNTIF($A$6:$A19,I20)=0)),"predecessora abaixo da tarefa","ok"))) -> ok | Q20: =IF(OR($D20="",$E20=""),"",IF(AND($D20<=Q$6+6,$E20>=Q$6),IF($N20="CRÍTICA","C","P"),"")) | R20: =IF(OR($D20="",$E20=""),"",IF(AND($D20<=R$6+6,$E20>=R$6),IF($N20="CRÍTICA","C","P"),"")) | S20: =IF(OR($D20="",$E20=""),"",IF(AND($D20<=S$6+6,$E20>=S$6),IF($N20="CRÍTICA","C","P"),"")) | T20: =IF(OR($D20="",$E20=""),"",IF(AND($D20<=T$6+6,$E20>=T$6),IF($N20="CRÍTICA","C","P"),"")) | U20: =IF(OR($D20="",$E20=""),"",IF(AND($D20<=U$6+6,$E20>=U$6),IF($N20="CRÍTICA","C","P"),"")) -> P | V20: =IF(OR($D20="",$E20=""),"",IF(AND($D20<=V$6+6,$E20>=V$6),IF($N20="CRÍTICA","C","P"),"")) -> P | W20: =IF(OR($D20="",$E20=""),"",IF(AND($D20<=W$6+6,$E20>=W$6),IF($N20="CRÍTICA","C","P"),"")) -> P | X20: =IF(OR($D20="",$E20=""),"",IF(AND($D20<=X$6+6,$E20>=X$6),IF($N20="CRÍTICA","C","P"),"")) -> P | ... BR20: =IF(OR($D20="",$E20=""),"",IF(AND($D20<=BR$6+6,$E20>=BR$6),IF($N20="CRÍTICA","C","P"),"")) | BT20: =IF(SUM($D46:$O46)=0,"",_xlfn.MINIFS($D$32:$O$32,$D46:$O46,">0")) -> 46296 | BU20: =IF(BT20="","",EOMONTH(_xlfn.MAXIFS($D$32:$O$32,$D46:$O46,">0"),0)) -> 46507 | BV20: Contrato | BW20: 343 | BX20: =IF(E20="","",IF(COUNTIF($G21:$G$28,$A20)+COUNTIF($H21:$H$28,$A20)+COUNTIF($I21:$I$28,$A20)=0,_xlfn.MAXIFS($E$7:$E$27,$BW$7:$BW$27,$BW20),MIN(IF(COUNTIF($G21:$G$28,$A20)>0,_xlfn.MINIFS($BY21:$BY$28,$G21:$G$28,$A20),99999999),IF(COUNTIF($H21:$H$28,$A20)>0,_xlfn.MINIFS($BY21:$BY$28,$H21:$H$28,$A20),99999999),IF(COUNTIF($I21:$I$28,$A20)>0,_xlfn.MINIFS($BY21:$BY$28,$I21:$I$28,$A20),99999999))-1)) -> 46538 | BY20: =IF(BX20="","",BX20-F20+1) -> 46327 | BZ20: =IF(AND(D20<>"",D20>DATA_GESTAO),D20+ROW()/1000000,"") | CA20: =SUMPRODUCT(($BW$7:$BW$27=$BW20)*($G$7:$I$27<>"")) -> 0
